Workbook

Sheet Inicio
B2: PLANILHA DE FINANÇAS & INVESTIMENTOS
B4: Controle financeiro • Orçamento • Carteira de investimentos • Patrimônio • Simulador • Independência financeira • Metas
B6: 📌 RESUMO DO MOMENTO (atualiza sozinho)
B7: PATRIMÔNIO LÍQUIDO | E7: RECEITAS NO ANO | H7: DESPESAS NO ANO | K7: TAXA DE POUPANÇA
B8: =Dashboard!B8 | E8: =Dashboard!B4 | H8: =Dashboard!G4 | K8: =Dashboard!Q4
B11: CARTEIRA (VALOR) | E11: PROGRESSO FIRE | H11: SALDO DO ANO | K11: RESERVA — % META
B12: =Dashboard!G8 | E12: =Dashboard!Q8 | H12: =Dashboard!B12 | K12: =Dashboard!Q12
B15: 🧭 NAVEGAÇÃO (clique para abrir a aba)
B16: 📊 Dashboard | H16: 💰 Lançamentos
B17: Visão geral, indicadores e gráficos | H17: Registre receitas, despesas e aportes
B19: 📅 Orçamento | H19: 📈 Carteira
B20: Planejado × realizado, mês a mês | H20: Ações, FIIs e ETFs com rebalanceamento
B22: 🏦 Patrimônio | H22: 🧮 Simulador
B23: Patrimônio líquido e reserva | H23: Projeção de juros compostos
B25: 🔥 Independência | H25: 🎯 Metas
B26: Quando você atinge a liberdade (FIRE) | H26: Objetivos e aporte mensal necessário
B28: 📖 Instruções | H28: ⚙️ Config
B29: Guia completo passo a passo | H29: Listas e categorias personalizáveis
B31: 🟡 VOCÊ PREENCHE | E31: ⬜ CÁLCULO AUTOMÁTICO
B33: 🟡 REGRA DE OURO: edite apenas as células amarelas e a aba Lançamentos. Todo o resto é calculado sozinho.

Sheet Dashboard
A1: 📊 PAINEL FINANCEIRO — VISÃO GERAL 2026 | R1: 🏠 Início
B3: RECEITAS NO ANO | G3: DESPESAS NO ANO | L3: INVESTIDO NO ANO | Q3: TAXA DE POUPANÇA
B4: =Orcamento!O26 | G4: =Orcamento!O17 | L4: =Orcamento!O28 | Q4: =IFERROR((Orcamento!O26-Orcamento!O17)/Orcamento!O26,0)
B7: PATRIMÔNIO LÍQUIDO | G7: CARTEIRA — VALOR ATUAL | L7: CARTEIRA — RESULTADO % | Q7: PROGRESSO FIRE
B8: =IFERROR(LOOKUP(2,1/(Patrimonio!G5:G16<>""),Patrimonio!G5:G16),0) | G8: =Carteira!G25 | L8: =IFERROR(Carteira!H25/(Carteira!G25-Carteira!H25),0) | Q8: =Independencia!B15
B11: SALDO DO ANO (SOBRA) | G11: DIVIDENDOS 12M (CARTEIRA) | L11: RENDA PASSIVA HOJE/MÊS | Q11: RESERVA — % DA META
B12: =Orcamento!O26-Orcamento!O17-Orcamento!O28 | G12: =Carteira!L25 | L12: =Independencia!B14 | Q12: =IFERROR(Patrimonio!B23,0)
B14: 📌 INSIGHTS AUTOMÁTICOS
B15: 🏆 Maior categoria de despesa | G15: =INDEX(Orcamento!$A$5:$A$16,MATCH(MAX(Orcamento!$O$5:$O$16),Orcamento!$O$5:$O$16,0)) | K15: 💵 Sobra média / mês | P15: =IFERROR(Orcamento!$O$29/COUNTIF(Orcamento!$C$17:$N$17,">0"),0)
B16: ↳ valor gasto no ano | G16: =MAX(Orcamento!$O$5:$O$16) | K16: 🎯 Aporte médio / mês | P16: =IFERROR(AVERAGEIF(Orcamento!$C$28:$N$28,">0"),0)
B17: 📈 Mês de maior gasto | G17: =INDEX(Orcamento!$C$4:$N$4,MATCH(MAX(Orcamento!$C$17:$N$17),Orcamento!$C$17:$N$17,0)) | K17: 🏦 Dividendos médios / mês | P17: =Carteira!$L$25/12
B18: 💸 Média de despesas / mês | G18: =IFERROR(AVERAGEIF(Orcamento!$C$17:$N$17,">0"),0) | K18: 📅 Meses já registrados | P18: =COUNTIF(Orcamento!$C$17:$N$17,">0")
B19: 💰 Média de receitas / mês | G19: =IFERROR(AVERAGEIF(Orcamento!$C$26:$N$26,">0"),0) | K19: 🔥 Anos até a independência | P19: =Independencia!$B$16
B58: 💡 Registre seus lançamentos diariamente na aba Lançamentos e atualize a Carteira e o Patrimônio mensalmente — todos os números, insights e gráficos deste painel se atualizam sozinhos.

Sheet Lancamentos
A1: 💰 CONTROLE FINANCEIRO — LANÇAMENTOS | H1: 🏠 Início
A2: Registre TODA entrada e saída. Use os menus suspensos. Mantenha em ordem de data e sem linhas em branco no meio para o Saldo em Caixa ficar correto. Mês e Saldo são automáticos.
A4: Data | B4: Tipo | C4: Categoria | D4: Descrição | E4: Valor (R$) | F4: Forma de Pagamento | G4: Mês | H4: Saldo em Caixa
A5: 46027 | B5: Receita | C5: Salário | D5: Salário mensal | E5: 8500 | F5: Transferência | G5: =IF($A5="","",MONTH($A5)) | H5: =IF($A5="","",SUMPRODUCT(($B$5:$B5="Receita")*$E$5:$E5)-SUMPRODUCT((($B$5:$B5="Despesa")+($B$5:$B5="Investimento"))*$E$5:$E5))
A6: 46027 | B6: Despesa | C6: Moradia | D6: Aluguel + condomínio | E6: 1800 | F6: Boleto | G6: =IF($A6="","",MONTH($A6)) | H6: =IF($A6="","",SUMPRODUCT(($B$5:$B6="Receita")*$E$5:$E6)-SUMPRODUCT((($B$5:$B6="Despesa")+($B$5:$B6="Investimento"))*$E$5:$E6))
A7: 46029 | B7: Despesa | C7: Assinaturas e Serviços | D7: Internet fibra | E7: 120 | F7: Débito Automático | G7: =IF($A7="","",MONTH($A7)) | H7: =IF($A7="","",SUMPRODUCT(($B$5:$B7="Receita")*$E$5:$E7)-SUMPRODUCT((($B$5:$B7="Despesa")+($B$5:$B7="Investimento"))*$E$5:$E7))
A8: 46030 | B8: Despesa | C8: Moradia | D8: Energia elétrica | E8: 210 | F8: Boleto | G8: =IF($A8="","",MONTH($A8)) | H8: =IF($A8="","",SUMPRODUCT(($B$5:$B8="Receita")*$E$5:$E8)-SUMPRODUCT((($B$5:$B8="Despesa")+($B$5:$B8="Investimento"))*$E$5:$E8))
A9: 46032 | B9: Despesa | C9: Saúde | D9: Plano de saúde | E9: 450 | F9: Débito Automático | G9: =IF($A9="","",MONTH($A9)) | H9: =IF($A9="","",SUMPRODUCT(($B$5:$B9="Receita")*$E$5:$E9)-SUMPRODUCT((($B$5:$B9="Despesa")+($B$5:$B9="Investimento"))*$E$5:$E9))
A10: 46032 | B10: Despesa | C10: Alimentação | D10: Supermercado do mês | E10: 980 | F10: Cartão de Crédito | G10: =IF($A10="","",MONTH($A10)) | H10: =IF($A10="","",SUMPRODUCT(($B$5:$B10="Receita")*$E$5:$E10)-SUMPRODUCT((($B$5:$B10="Despesa")+($B$5:$B10="Investimento"))*$E$5:$E10))
A11: 46034 | B11: Despesa | C11: Transporte | D11: Combustível | E11: 340 | F11: Cartão de Crédito | G11: =IF($A11="","",MONTH($A11)) | H11: =IF($A11="","",SUMPRODUCT(($B$5:$B11="Receita")*$E$5:$E11)-SUMPRODUCT((($B$5:$B11="Despesa")+($B$5:$B11="Investimento"))*$E$5:$E11))
A12: 46037 | B12: Investimento | C12: Aporte Investimentos | D12: Aporte na corretora | E12: 1500 | F12: Pix | G12: =IF($A12="","",MONTH($A12)) | H12: =IF($A12="","",SUMPRODUCT(($B$5:$B12="Receita")*$E$5:$E12)-SUMPRODUCT((($B$5:$B12="Despesa")+($B$5:$B12="Investimento"))*$E$5:$E12))
A13: 46037 | B13: Despesa | C13: Transporte | D13: IPVA 2026 (cota única) | E13: 1450 | F13: Pix | G13: =IF($A13="","",MONTH($A13)) | H13: =IF($A13="","",SUMPRODUCT(($B$5:$B13="Receita")*$E$5:$E13)-SUMPRODUCT((($B$5:$B13="Despesa")+($B$5:$B13="Investimento"))*$E$5:$E13))
A14: 46040 | B14: Despesa | C14: Lazer | D14: Restaurantes e delivery | E14: 260 | F14: Cartão de Crédito | G14: =IF($A14="","",MONTH($A14)) | H14: =IF($A14="","",SUMPRODUCT(($B$5:$B14="Receita")*$E$5:$E14)-SUMPRODUCT((($B$5:$B14="Despesa")+($B$5:$B14="Investimento"))*$E$5:$E14))
A15: 46042 | B15: Despesa | C15: Saúde | D15: Academia | E15: 110 | F15: Débito Automático | G15: =IF($A15="","",MONTH($A15)) | H15: =IF($A15="","",SUMPRODUCT(($B$5:$B15="Receita")*$E$5:$E15)-SUMPRODUCT((($B$5:$B15="Despesa")+($B$5:$B15="Investimento"))*$E$5:$E15))
A16: 46042 | B16: Despesa | C16: Educação | D16: Material escolar | E16: 320 | F16: Cartão de Crédito | G16: =IF($A16="","",MONTH($A16)) | H16: =IF($A16="","",SUMPRODUCT(($B$5:$B16="Receita")*$E$5:$E16)-SUMPRODUCT((($B$5:$B16="Despesa")+($B$5:$B16="Investimento"))*$E$5:$E16))
... A92: 46200 | B92: Despesa | C92: Alimentação | D92: Feira e padaria | E92: 178 | F92: Pix | G92: =IF($A92="","",MONTH($A92)) | H92: =IF($A92="","",SUMPRODUCT(($B$5:$B92="Receita")*$E$5:$E92)-SUMPRODUCT((($B$5:$B92="Despesa")+($B$5:$B92="Investimento"))*$E$5:$E92))
G93: =IF($A93="","",MONTH($A93)) | H93: =IF($A93="","",SUMPRODUCT(($B$5:$B93="Receita")*$E$5:$E93)-SUMPRODUCT((($B$5:$B93="Despesa")+($B$5:$B93="Investimento"))*$E$5:$E93))
G94: =IF($A94="","",MONTH($A94)) | H94: =IF($A94="","",SUMPRODUCT(($B$5:$B94="Receita")*$E$5:$E94)-SUMPRODUCT((($B$5:$B94="Despesa")+($B$5:$B94="Investimento"))*$E$5:$E94))
G95: =IF($A95="","",MONTH($A95)) | H95: =IF($A95="","",SUMPRODUCT(($B$5:$B95="Receita")*$E$5:$E95)-SUMPRODUCT((($B$5:$B95="Despesa")+($B$5:$B95="Investimento"))*$E$5:$E95))
G96: =IF($A96="","",MONTH($A96)) | H96: =IF($A96="","",SUMPRODUCT(($B$5:$B96="Receita")*$E$5:$E96)-SUMPRODUCT((($B$5:$B96="Despesa")+($B$5:$B96="Investimento"))*$E$5:$E96))
G97: =IF($A97="","",MONTH($A97)) | H97: =IF($A97="","",SUMPRODUCT(($B$5:$B97="Receita")*$E$5:$E97)-SUMPRODUCT((($B$5:$B97="Despesa")+($B$5:$B97="Investimento"))*$E$5:$E97))
G98: =IF($A98="","",MONTH($A98)) | H98: =IF($A98="","",SUMPRODUCT(($B$5:$B98="Receita")*$E$5:$E98)-SUMPRODUCT((($B$5:$B98="Despesa")+($B$5:$B98="Investimento"))*$E$5:$E98))
G99: =IF($A99="","",MONTH($A99)) | H99: =IF($A99="","",SUMPRODUCT(($B$5:$B99="Receita")*$E$5:$E99)-SUMPRODUCT((($B$5:$B99="Despesa")+($B$5:$B99="Investimento"))*$E$5:$E99))
G100: =IF($A100="","",MONTH($A100)) | H100: =IF($A100="","",SUMPRODUCT(($B$5:$B100="Receita")*$E$5:$E100)-SUMPRODUCT((($B$5:$B100="Despesa")+($B$5:$B100="Investimento"))*$E$5:$E100))
G101: =IF($A101="","",MONTH($A101)) | H101: =IF($A101="","",SUMPRODUCT(($B$5:$B101="Receita")*$E$5:$E101)-SUMPRODUCT((($B$5:$B101="Despesa")+($B$5:$B101="Investimento"))*$E$5:$E101))
G102: =IF($A102="","",MONTH($A102)) | H102: =IF($A102="","",SUMPRODUCT(($B$5:$B102="Receita")*$E$5:$E102)-SUMPRODUCT((($B$5:$B102="Despesa")+($B$5:$B102="Investimento"))*$E$5:$E102))
G103: =IF($A103="","",MONTH($A103)) | H103: =IF($A103="","",SUMPRODUCT(($B$5:$B103="Receita")*$E$5:$E103)-SUMPRODUCT((($B$5:$B103="Despesa")+($B$5:$B103="Investimento"))*$E$5:$E103))
G104: =IF($A104="","",MONTH($A104)) | H104: =IF($A104="","",SUMPRODUCT(($B$5:$B104="Receita")*$E$5:$E104)-SUMPRODUCT((($B$5:$B104="Despesa")+($B$5:$B104="Investimento"))*$E$5:$E104))
... G504: =IF($A504="","",MONTH($A504)) | H504: =IF($A504="","",SUMPRODUCT(($B$5:$B504="Receita")*$E$5:$E504)-SUMPRODUCT((($B$5:$B504="Despesa")+($B$5:$B504="Investimento"))*$E$5:$E504))

Sheet Orcamento
A1: 📅 ORÇAMENTO DOMÉSTICO — PLANEJADO × REALIZADO | R1: 🏠 Início
A2: Defina o orçamento mensal na coluna B (células amarelas). O realizado vem da aba Lançamentos. Vermelho = mês acima do orçado. A coluna % Usado mostra o consumo do orçamento anual.
C3: 1 | D3: 2 | E3: 3 | F3: 4 | G3: 5 | H3: 6 | I3: 7 | J3: 8 | K3: 9 | L3: 10 | M3: 11 | N3: 12
A4: DESPESAS — Categoria | B4: Orçado / Mês | C4: Jan | D4: Fev | E4: Mar | F4: Abr | G4: Mai | H4: Jun | I4: Jul | J4: Ago | K4: Set | L4: Out | M4: Nov | N4: Dez | O4: Total Ano | P4: Média / Mês | Q4: Orçado / Ano | R4: % Usado
A5: Moradia | B5: 2200 | C5: =SUMIFS(Lancamentos!$E$5:$E$504,Lancamentos!$B$5:$B$504,"Despesa",Lancamentos!$C$5:$C$504,$A5,Lancamentos!$G$5:$G$504,C$3) | D5: =SUMIFS(Lancamentos!$E$5:$E$504,Lancamentos!$B$5:$B$504,"Despesa",Lancamentos!$C$5:$C$504,$A5,Lancamentos!$G$5:$G$504,D$3) | E5: =SUMIFS(Lancamentos!$E$5:$E$504,Lancamentos!$B$5:$B$504,"Despesa",Lancamentos!$C$5:$C$504,$A5,Lancamentos!$G$5:$G$504,E$3) | F5: =SUMIFS(Lancamentos!$E$5:$E$504,Lancamentos!$B$5:$B$504,"Despesa",Lancamentos!$C$5:$C$504,$A5,Lancamentos!$G$5:$G$504,F$3) | G5: =SUMIFS(Lancamentos!$E$5:$E$504,Lancamentos!$B$5:$B$504,"Despesa",Lancamentos!$C$5:$C$504,$A5,Lancamentos!$G$5:$G$504,G$3) | H5: =SUMIFS(Lancamentos!$E$5:$E$504,Lancamentos!$B$5:$B$504,"Despesa",Lancamentos!$C$5:$C$504,$A5,Lancamentos!$G$5:$G$504,H$3) | I5: =SUMIFS(Lancamentos!$E$5:$E$504,Lancamentos!$B$5:$B$504,"Despesa",Lancamentos!$C$5:$C$504,$A5,Lancamentos!$G$5:$G$504,I$3) | J5: =SUMIFS(Lancamentos!$E$5:$E$504,Lancamentos!$B$5:$B$504,"Despesa",Lancamentos!$C$5:$C$504,$A5,Lancamentos!$G$5:$G$504,J$3) | ... N5: =SUMIFS(Lancamentos!$E$5:$E$504,Lancamentos!$B$5:$B$504,"Despesa",Lancamentos!$C$5:$C$504,$A5,Lancamentos!$G$5:$G$504,N$3) | O5: =SUM(C5:N5) | P5: =AVERAGE(C5:N5) | Q5: =B5*12 | R5: =IFERROR(O5/Q5,"")
A6: Alimentação | B6: 1400 | C6: =SUMIFS(Lancamentos!$E$5:$E$504,Lancamentos!$B$5:$B$504,"Despesa",Lancamentos!$C$5:$C$504,$A6,Lancamentos!$G$5:$G$504,C$3) | D6: =SUMIFS(Lancamentos!$E$5:$E$504,Lancamentos!$B$5:$B$504,"Despesa",Lancamentos!$C$5:$C$504,$A6,Lancamentos!$G$5:$G$504,D$3) | E6: =SUMIFS(Lancamentos!$E$5:$E$504,Lancamentos!$B$5:$B$504,"Despesa",Lancamentos!$C$5:$C$504,$A6,Lancamentos!$G$5:$G$504,E$3) | F6: =SUMIFS(Lancamentos!$E$5:$E$504,Lancamentos!$B$5:$B$504,"Despesa",Lancamentos!$C$5:$C$504,$A6,Lancamentos!$G$5:$G$504,F$3) | G6: =SUMIFS(Lancamentos!$E$5:$E$504,Lancamentos!$B$5:$B$504,"Despesa",Lancamentos!$C$5:$C$504,$A6,Lancamentos!$G$5:$G$504,G$3) | H6: =SUMIFS(Lancamentos!$E$5:$E$504,Lancamentos!$B$5:$B$504,"Despesa",Lancamentos!$C$5:$C$504,$A6,Lancamentos!$G$5:$G$504,H$3) | I6: =SUMIFS(Lancamentos!$E$5:$E$504,Lancamentos!$B$5:$B$504,"Despesa",Lancamentos!$C$5:$C$504,$A6,Lancamentos!$G$5:$G$504,I$3) | J6: =SUMIFS(Lancamentos!$E$5:$E$504,Lancamentos!$B$5:$B$504,"Despesa",Lancamentos!$C$5:$C$504,$A6,Lancamentos!$G$5:$G$504,J$3) | ... N6: =SUMIFS(Lancamentos!$E$5:$E$504,Lancamentos!$B$5:$B$504,"Despesa",Lancamentos!$C$5:$C$504,$A6,Lancamentos!$G$5:$G$504,N$3) | O6: =SUM(C6:N6) | P6: =AVERAGE(C6:N6) | Q6: =B6*12 | R6: =IFERROR(O6/Q6,"")
A7: Transporte | B7: 700 | C7: =SUMIFS(Lancamentos!$E$5:$E$504,Lancamentos!$B$5:$B$504,"Despesa",Lancamentos!$C$5:$C$504,$A7,Lancamentos!$G$5:$G$504,C$3) | D7: =SUMIFS(Lancamentos!$E$5:$E$504,Lancamentos!$B$5:$B$504,"Despesa",Lancamentos!$C$5:$C$504,$A7,Lancamentos!$G$5:$G$504,D$3) | E7: =SUMIFS(Lancamentos!$E$5:$E$504,Lancamentos!$B$5:$B$504,"Despesa",Lancamentos!$C$5:$C$504,$A7,Lancamentos!$G$5:$G$504,E$3) | F7: =SUMIFS(Lancamentos!$E$5:$E$504,Lancamentos!$B$5:$B$504,"Despesa",Lancamentos!$C$5:$C$504,$A7,Lancamentos!$G$5:$G$504,F$3) | G7: =SUMIFS(Lancamentos!$E$5:$E$504,Lancamentos!$B$5:$B$504,"Despesa",Lancamentos!$C$5:$C$504,$A7,Lancamentos!$G$5:$G$504,G$3) | H7: =SUMIFS(Lancamentos!$E$5:$E$504,Lancamentos!$B$5:$B$504,"Despesa",Lancamentos!$C$5:$C$504,$A7,Lancamentos!$G$5:$G$504,H$3) | I7: =SUMIFS(Lancamentos!$E$5:$E$504,Lancamentos!$B$5:$B$504,"Despesa",Lancamentos!$C$5:$C$504,$A7,Lancamentos!$G$5:$G$504,I$3) | J7: =SUMIFS(Lancamentos!$E$5:$E$504,Lancamentos!$B$5:$B$504,"Despesa",Lancamentos!$C$5:$C$504,$A7,Lancamentos!$G$5:$G$504,J$3) | ... N7: =SUMIFS(Lancamentos!$E$5:$E$504,Lancamentos!$B$5:$B$504,"Despesa",Lancamentos!$C$5:$C$504,$A7,Lancamentos!$G$5:$G$504,N$3) | O7: =SUM(C7:N7) | P7: =AVERAGE(C7:N7) | Q7: =B7*12 | R7: =IFERROR(O7/Q7,"")
A8: Saúde | B8: 600 | C8: =SUMIFS(Lancamentos!$E$5:$E$504,Lancamentos!$B$5:$B$504,"Despesa",Lancamentos!$C$5:$C$504,$A8,Lancamentos!$G$5:$G$504,C$3) | D8: =SUMIFS(Lancamentos!$E$5:$E$504,Lancamentos!$B$5:$B$504,"Despesa",Lancamentos!$C$5:$C$504,$A8,Lancamentos!$G$5:$G$504,D$3) | E8: =SUMIFS(Lancamentos!$E$5:$E$504,Lancamentos!$B$5:$B$504,"Despesa",Lancamentos!$C$5:$C$504,$A8,Lancamentos!$G$5:$G$504,E$3) | F8: =SUMIFS(Lancamentos!$E$5:$E$504,Lancamentos!$B$5:$B$504,"Despesa",Lancamentos!$C$5:$C$504,$A8,Lancamentos!$G$5:$G$504,F$3) | G8: =SUMIFS(Lancamentos!$E$5:$E$504,Lancamentos!$B$5:$B$504,"Despesa",Lancamentos!$C$5:$C$504,$A8,Lancamentos!$G$5:$G$504,G$3) | H8: =SUMIFS(Lancamentos!$E$5:$E$504,Lancamentos!$B$5:$B$504,"Despesa",Lancamentos!$C$5:$C$504,$A8,Lancamentos!$G$5:$G$504,H$3) | I8: =SUMIFS(Lancamentos!$E$5:$E$504,Lancamentos!$B$5:$B$504,"Despesa",Lancamentos!$C$5:$C$504,$A8,Lancamentos!$G$5:$G$504,I$3) | J8: =SUMIFS(Lancamentos!$E$5:$E$504,Lancamentos!$B$5:$B$504,"Despesa",Lancamentos!$C$5:$C$504,$A8,Lancamentos!$G$5:$G$504,J$3) | ... N8: =SUMIFS(Lancamentos!$E$5:$E$504,Lancamentos!$B$5:$B$504,"Despesa",Lancamentos!$C$5:$C$504,$A8,Lancamentos!$G$5:$G$504,N$3) | O8: =SUM(C8:N8) | P8: =AVERAGE(C8:N8) | Q8: =B8*12 | R8: =IFERROR(O8/Q8,"")
A9: Educação | B9: 350 | C9: =SUMIFS(Lancamentos!$E$5:$E$504,Lancamentos!$B$5:$B$504,"Despesa",Lancamentos!$C$5:$C$504,$A9,Lancamentos!$G$5:$G$504,C$3) | D9: =SUMIFS(Lancamentos!$E$5:$E$504,Lancamentos!$B$5:$B$504,"Despesa",Lancamentos!$C$5:$C$504,$A9,Lancamentos!$G$5:$G$504,D$3) | E9: =SUMIFS(Lancamentos!$E$5:$E$504,Lancamentos!$B$5:$B$504,"Despesa",Lancamentos!$C$5:$C$504,$A9,Lancamentos!$G$5:$G$504,E$3) | F9: =SUMIFS(Lancamentos!$E$5:$E$504,Lancamentos!$B$5:$B$504,"Despesa",Lancamentos!$C$5:$C$504,$A9,Lancamentos!$G$5:$G$504,F$3) | G9: =SUMIFS(Lancamentos!$E$5:$E$504,Lancamentos!$B$5:$B$504,"Despesa",Lancamentos!$C$5:$C$504,$A9,Lancamentos!$G$5:$G$504,G$3) | H9: =SUMIFS(Lancamentos!$E$5:$E$504,Lancamentos!$B$5:$B$504,"Despesa",Lancamentos!$C$5:$C$504,$A9,Lancamentos!$G$5:$G$504,H$3) | I9: =SUMIFS(Lancamentos!$E$5:$E$504,Lancamentos!$B$5:$B$504,"Despesa",Lancamentos!$C$5:$C$504,$A9,Lancamentos!$G$5:$G$504,I$3) | J9: =SUMIFS(Lancamentos!$E$5:$E$504,Lancamentos!$B$5:$B$504,"Despesa",Lancamentos!$C$5:$C$504,$A9,Lancamentos!$G$5:$G$504,J$3) | ... N9: =SUMIFS(Lancamentos!$E$5:$E$504,Lancamentos!$B$5:$B$504,"Despesa",Lancamentos!$C$5:$C$504,$A9,Lancamentos!$G$5:$G$504,N$3) | O9: =SUM(C9:N9) | P9: =AVERAGE(C9:N9) | Q9: =B9*12 | R9: =IFERROR(O9/Q9,"")
A10: Lazer | B10: 450 | C10: =SUMIFS(Lancamentos!$E$5:$E$504,Lancamentos!$B$5:$B$504,"Despesa",Lancamentos!$C$5:$C$504,$A10,Lancamentos!$G$5:$G$504,C$3) | D10: =SUMIFS(Lancamentos!$E$5:$E$504,Lancamentos!$B$5:$B$504,"Despesa",Lancamentos!$C$5:$C$504,$A10,Lancamentos!$G$5:$G$504,D$3) | E10: =SUMIFS(Lancamentos!$E$5:$E$504,Lancamentos!$B$5:$B$504,"Despesa",Lancamentos!$C$5:$C$504,$A10,Lancamentos!$G$5:$G$504,E$3) | F10: =SUMIFS(Lancamentos!$E$5:$E$504,Lancamentos!$B$5:$B$504,"Despesa",Lancamentos!$C$5:$C$504,$A10,Lancamentos!$G$5:$G$504,F$3) | G10: =SUMIFS(Lancamentos!$E$5:$E$504,Lancamentos!$B$5:$B$504,"Despesa",Lancamentos!$C$5:$C$504,$A10,Lancamentos!$G$5:$G$504,G$3) | H10: =SUMIFS(Lancamentos!$E$5:$E$504,Lancamentos!$B$5:$B$504,"Despesa",Lancamentos!$C$5:$C$504,$A10,Lancamentos!$G$5:$G$504,H$3) | I10: =SUMIFS(Lancamentos!$E$5:$E$504,Lancamentos!$B$5:$B$504,"Despesa",Lancamentos!$C$5:$C$504,$A10,Lancamentos!$G$5:$G$504,I$3) | J10: =SUMIFS(Lancamentos!$E$5:$E$504,Lancamentos!$B$5:$B$504,"Despesa",Lancamentos!$C$5:$C$504,$A10,Lancamentos!$G$5:$G$504,J$3) | ... N10: =SUMIFS(Lancamentos!$E$5:$E$504,Lancamentos!$B$5:$B$504,"Despesa",Lancamentos!$C$5:$C$504,$A10,Lancamentos!$G$5:$G$504,N$3) | O10: =SUM(C10:N10) | P10: =AVERAGE(C10:N10) | Q10: =B10*12 | R10: =IFERROR(O10/Q10,"")
A11: Vestuário | B11: 250 | C11: =SUMIFS(Lancamentos!$E$5:$E$504,Lancamentos!$B$5:$B$504,"Despesa",Lancamentos!$C$5:$C$504,$A11,Lancamentos!$G$5:$G$504,C$3) | D11: =SUMIFS(Lancamentos!$E$5:$E$504,Lancamentos!$B$5:$B$504,"Despesa",Lancamentos!$C$5:$C$504,$A11,Lancamentos!$G$5:$G$504,D$3) | E11: =SUMIFS(Lancamentos!$E$5:$E$504,Lancamentos!$B$5:$B$504,"Despesa",Lancamentos!$C$5:$C$504,$A11,Lancamentos!$G$5:$G$504,E$3) | F11: =SUMIFS(Lancamentos!$E$5:$E$504,Lancamentos!$B$5:$B$504,"Despesa",Lancamentos!$C$5:$C$504,$A11,Lancamentos!$G$5:$G$504,F$3) | G11: =SUMIFS(Lancamentos!$E$5:$E$504,Lancamentos!$B$5:$B$504,"Despesa",Lancamentos!$C$5:$C$504,$A11,Lancamentos!$G$5:$G$504,G$3) | H11: =SUMIFS(Lancamentos!$E$5:$E$504,Lancamentos!$B$5:$B$504,"Despesa",Lancamentos!$C$5:$C$504,$A11,Lancamentos!$G$5:$G$504,H$3) | I11: =SUMIFS(Lancamentos!$E$5:$E$504,Lancamentos!$B$5:$B$504,"Despesa",Lancamentos!$C$5:$C$504,$A11,Lancamentos!$G$5:$G$504,I$3) | J11: =SUMIFS(Lancamentos!$E$5:$E$504,Lancamentos!$B$5:$B$504,"Despesa",Lancamentos!$C$5:$C$504,$A11,Lancamentos!$G$5:$G$504,J$3) | ... N11: =SUMIFS(Lancamentos!$E$5:$E$504,Lancamentos!$B$5:$B$504,"Despesa",Lancamentos!$C$5:$C$504,$A11,Lancamentos!$G$5:$G$504,N$3) | O11: =SUM(C11:N11) | P11: =AVERAGE(C11:N11) | Q11: =B11*12 | R11: =IFERROR(O11/Q11,"")
A12: Assinaturas e Serviços | B12: 200 | C12: =SUMIFS(Lancamentos!$E$5:$E$504,Lancamentos!$B$5:$B$504,"Despesa",Lancamentos!$C$5:$C$504,$A12,Lancamentos!$G$5:$G$504,C$3) | D12: =SUMIFS(Lancamentos!$E$5:$E$504,Lancamentos!$B$5:$B$504,"Despesa",Lancamentos!$C$5:$C$504,$A12,Lancamentos!$G$5:$G$504,D$3) | E12: =SUMIFS(Lancamentos!$E$5:$E$504,Lancamentos!$B$5:$B$504,"Despesa",Lancamentos!$C$5:$C$504,$A12,Lancamentos!$G$5:$G$504,E$3) | F12: =SUMIFS(Lancamentos!$E$5:$E$504,Lancamentos!$B$5:$B$504,"Despesa",Lancamentos!$C$5:$C$504,$A12,Lancamentos!$G$5:$G$504,F$3) | G12: =SUMIFS(Lancamentos!$E$5:$E$504,Lancamentos!$B$5:$B$504,"Despesa",Lancamentos!$C$5:$C$504,$A12,Lancamentos!$G$5:$G$504,G$3) | H12: =SUMIFS(Lancamentos!$E$5:$E$504,Lancamentos!$B$5:$B$504,"Despesa",Lancamentos!$C$5:$C$504,$A12,Lancamentos!$G$5:$G$504,H$3) | I12: =SUMIFS(Lancamentos!$E$5:$E$504,Lancamentos!$B$5:$B$504,"Despesa",Lancamentos!$C$5:$C$504,$A12,Lancamentos!$G$5:$G$504,I$3) | J12: =SUMIFS(Lancamentos!$E$5:$E$504,Lancamentos!$B$5:$B$504,"Despesa",Lancamentos!$C$5:$C$504,$A12,Lancamentos!$G$5:$G$504,J$3) | ... N12: =SUMIFS(Lancamentos!$E$5:$E$504,Lancamentos!$B$5:$B$504,"Despesa",Lancamentos!$C$5:$C$504,$A12,Lancamentos!$G$5:$G$504,N$3) | O12: =SUM(C12:N12) | P12: =AVERAGE(C12:N12) | Q12: =B12*12 | R12: =IFERROR(O12/Q12,"")
A13: Dívidas e Empréstimos | B13: 0 | C13: =SUMIFS(Lancamentos!$E$5:$E$504,Lancamentos!$B$5:$B$504,"Despesa",Lancamentos!$C$5:$C$504,$A13,Lancamentos!$G$5:$G$504,C$3) | D13: =SUMIFS(Lancamentos!$E$5:$E$504,Lancamentos!$B$5:$B$504,"Despesa",Lancamentos!$C$5:$C$504,$A13,Lancamentos!$G$5:$G$504,D$3) | E13: =SUMIFS(Lancamentos!$E$5:$E$504,Lancamentos!$B$5:$B$504,"Despesa",Lancamentos!$C$5:$C$504,$A13,Lancamentos!$G$5:$G$504,E$3) | F13: =SUMIFS(Lancamentos!$E$5:$E$504,Lancamentos!$B$5:$B$504,"Despesa",Lancamentos!$C$5:$C$504,$A13,Lancamentos!$G$5:$G$504,F$3) | G13: =SUMIFS(Lancamentos!$E$5:$E$504,Lancamentos!$B$5:$B$504,"Despesa",Lancamentos!$C$5:$C$504,$A13,Lancamentos!$G$5:$G$504,G$3) | H13: =SUMIFS(Lancamentos!$E$5:$E$504,Lancamentos!$B$5:$B$504,"Despesa",Lancamentos!$C$5:$C$504,$A13,Lancamentos!$G$5:$G$504,H$3) | I13: =SUMIFS(Lancamentos!$E$5:$E$504,Lancamentos!$B$5:$B$504,"Despesa",Lancamentos!$C$5:$C$504,$A13,Lancamentos!$G$5:$G$504,I$3) | J13: =SUMIFS(Lancamentos!$E$5:$E$504,Lancamentos!$B$5:$B$504,"Despesa",Lancamentos!$C$5:$C$504,$A13,Lancamentos!$G$5:$G$504,J$3) | ... N13: =SUMIFS(Lancamentos!$E$5:$E$504,Lancamentos!$B$5:$B$504,"Despesa",Lancamentos!$C$5:$C$504,$A13,Lancamentos!$G$5:$G$504,N$3) | O13: =SUM(C13:N13) | P13: =AVERAGE(C13:N13) | Q13: =B13*12 | R13: =IFERROR(O13/Q13,"")
A14: Pets | B14: 250 | C14: =SUMIFS(Lancamentos!$E$5:$E$504,Lancamentos!$B$5:$B$504,"Despesa",Lancamentos!$C$5:$C$504,$A14,Lancamentos!$G$5:$G$504,C$3) | D14: =SUMIFS(Lancamentos!$E$5:$E$504,Lancamentos!$B$5:$B$504,"Despesa",Lancamentos!$C$5:$C$504,$A14,Lancamentos!$G$5:$G$504,D$3) | E14: =SUMIFS(Lancamentos!$E$5:$E$504,Lancamentos!$B$5:$B$504,"Despesa",Lancamentos!$C$5:$C$504,$A14,Lancamentos!$G$5:$G$504,E$3) | F14: =SUMIFS(Lancamentos!$E$5:$E$504,Lancamentos!$B$5:$B$504,"Despesa",Lancamentos!$C$5:$C$504,$A14,Lancamentos!$G$5:$G$504,F$3) | G14: =SUMIFS(Lancamentos!$E$5:$E$504,Lancamentos!$B$5:$B$504,"Despesa",Lancamentos!$C$5:$C$504,$A14,Lancamentos!$G$5:$G$504,G$3) | H14: =SUMIFS(Lancamentos!$E$5:$E$504,Lancamentos!$B$5:$B$504,"Despesa",Lancamentos!$C$5:$C$504,$A14,Lancamentos!$G$5:$G$504,H$3) | I14: =SUMIFS(Lancamentos!$E$5:$E$504,Lancamentos!$B$5:$B$504,"Despesa",Lancamentos!$C$5:$C$504,$A14,Lancamentos!$G$5:$G$504,I$3) | J14: =SUMIFS(Lancamentos!$E$5:$E$504,Lancamentos!$B$5:$B$504,"Despesa",Lancamentos!$C$5:$C$504,$A14,Lancamentos!$G$5:$G$504,J$3) | ... N14: =SUMIFS(Lancamentos!$E$5:$E$504,Lancamentos!$B$5:$B$504,"Despesa",Lancamentos!$C$5:$C$504,$A14,Lancamentos!$G$5:$G$504,N$3) | O14: =SUM(C14:N14) | P14: =AVERAGE(C14:N14) | Q14: =B14*12 | R14: =IFERROR(O14/Q14,"")
A15: Doações | B15: 100 | C15: =SUMIFS(Lancamentos!$E$5:$E$504,Lancamentos!$B$5:$B$504,"Despesa",Lancamentos!$C$5:$C$504,$A15,Lancamentos!$G$5:$G$504,C$3) | D15: =SUMIFS(Lancamentos!$E$5:$E$504,Lancamentos!$B$5:$B$504,"Despesa",Lancamentos!$C$5:$C$504,$A15,Lancamentos!$G$5:$G$504,D$3) | E15: =SUMIFS(Lancamentos!$E$5:$E$504,Lancamentos!$B$5:$B$504,"Despesa",Lancamentos!$C$5:$C$504,$A15,Lancamentos!$G$5:$G$504,E$3) | F15: =SUMIFS(Lancamentos!$E$5:$E$504,Lancamentos!$B$5:$B$504,"Despesa",Lancamentos!$C$5:$C$504,$A15,Lancamentos!$G$5:$G$504,F$3) | G15: =SUMIFS(Lancamentos!$E$5:$E$504,Lancamentos!$B$5:$B$504,"Despesa",Lancamentos!$C$5:$C$504,$A15,Lancamentos!$G$5:$G$504,G$3) | H15: =SUMIFS(Lancamentos!$E$5:$E$504,Lancamentos!$B$5:$B$504,"Despesa",Lancamentos!$C$5:$C$504,$A15,Lancamentos!$G$5:$G$504,H$3) | I15: =SUMIFS(Lancamentos!$E$5:$E$504,Lancamentos!$B$5:$B$504,"Despesa",Lancamentos!$C$5:$C$504,$A15,Lancamentos!$G$5:$G$504,I$3) | J15: =SUMIFS(Lancamentos!$E$5:$E$504,Lancamentos!$B$5:$B$504,"Despesa",Lancamentos!$C$5:$C$504,$A15,Lancamentos!$G$5:$G$504,J$3) | ... N15: =SUMIFS(Lancamentos!$E$5:$E$504,Lancamentos!$B$5:$B$504,"Despesa",Lancamentos!$C$5:$C$504,$A15,Lancamentos!$G$5:$G$504,N$3) | O15: =SUM(C15:N15) | P15: =AVERAGE(C15:N15) | Q15: =B15*12 | R15: =IFERROR(O15/Q15,"")
A16: Outros | B16: 250 | C16: =SUMIFS(Lancamentos!$E$5:$E$504,Lancamentos!$B$5:$B$504,"Despesa",Lancamentos!$C$5:$C$504,$A16,Lancamentos!$G$5:$G$504,C$3) | D16: =SUMIFS(Lancamentos!$E$5:$E$504,Lancamentos!$B$5:$B$504,"Despesa",Lancamentos!$C$5:$C$504,$A16,Lancamentos!$G$5:$G$504,D$3) | E16: =SUMIFS(Lancamentos!$E$5:$E$504,Lancamentos!$B$5:$B$504,"Despesa",Lancamentos!$C$5:$C$504,$A16,Lancamentos!$G$5:$G$504,E$3) | F16: =SUMIFS(Lancamentos!$E$5:$E$504,Lancamentos!$B$5:$B$504,"Despesa",Lancamentos!$C$5:$C$504,$A16,Lancamentos!$G$5:$G$504,F$3) | G16: =SUMIFS(Lancamentos!$E$5:$E$504,Lancamentos!$B$5:$B$504,"Despesa",Lancamentos!$C$5:$C$504,$A16,Lancamentos!$G$5:$G$504,G$3) | H16: =SUMIFS(Lancamentos!$E$5:$E$504,Lancamentos!$B$5:$B$504,"Despesa",Lancamentos!$C$5:$C$504,$A16,Lancamentos!$G$5:$G$504,H$3) | I16: =SUMIFS(Lancamentos!$E$5:$E$504,Lancamentos!$B$5:$B$504,"Despesa",Lancamentos!$C$5:$C$504,$A16,Lancamentos!$G$5:$G$504,I$3) | J16: =SUMIFS(Lancamentos!$E$5:$E$504,Lancamentos!$B$5:$B$504,"Despesa",Lancamentos!$C$5:$C$504,$A16,Lancamentos!$G$5:$G$504,J$3) | ... N16: =SUMIFS(Lancamentos!$E$5:$E$504,Lancamentos!$B$5:$B$504,"Despesa",Lancamentos!$C$5:$C$504,$A16,Lancamentos!$G$5:$G$504,N$3) | O16: =SUM(C16:N16) | P16: =AVERAGE(C16:N16) | Q16: =B16*12 | R16: =IFERROR(O16/Q16,"")
A17: TOTAL DE DESPESAS | B17: =SUM(B5:B16) | C17: =SUM(C5:C16) | D17: =SUM(D5:D16) | E17: =SUM(E5:E16) | F17: =SUM(F5:F16) | G17: =SUM(G5:G16) | H17: =SUM(H5:H16) | I17: =SUM(I5:I16) | ... N17: =SUM(N5:N16) | O17: =SUM(C17:N17) | P17: =AVERAGE(C17:N17) | Q17: =B17*12 | R17: =IFERROR(O17/Q17,"")
A19: RECEITAS
A20: Salário | C20: =SUMIFS(Lancamentos!$E$5:$E$504,Lancamentos!$B$5:$B$504,"Receita",Lancamentos!$C$5:$C$504,$A20,Lancamentos!$G$5:$G$504,C$3) | D20: =SUMIFS(Lancamentos!$E$5:$E$504,Lancamentos!$B$5:$B$504,"Receita",Lancamentos!$C$5:$C$504,$A20,Lancamentos!$G$5:$G$504,D$3) | E20: =SUMIFS(Lancamentos!$E$5:$E$504,Lancamentos!$B$5:$B$504,"Receita",Lancamentos!$C$5:$C$504,$A20,Lancamentos!$G$5:$G$504,E$3) | F20: =SUMIFS(Lancamentos!$E$5:$E$504,Lancamentos!$B$5:$B$504,"Receita",Lancamentos!$C$5:$C$504,$A20,Lancamentos!$G$5:$G$504,F$3) | G20: =SUMIFS(Lancamentos!$E$5:$E$504,Lancamentos!$B$5:$B$504,"Receita",Lancamentos!$C$5:$C$504,$A20,Lancamentos!$G$5:$G$504,G$3) | H20: =SUMIFS(Lancamentos!$E$5:$E$504,Lancamentos!$B$5:$B$504,"Receita",Lancamentos!$C$5:$C$504,$A20,Lancamentos!$G$5:$G$504,H$3) | I20: =SUMIFS(Lancamentos!$E$5:$E$504,Lancamentos!$B$5:$B$504,"Receita",Lancamentos!$C$5:$C$504,$A20,Lancamentos!$G$5:$G$504,I$3) | J20: =SUMIFS(Lancamentos!$E$5:$E$504,Lancamentos!$B$5:$B$504,"Receita",Lancamentos!$C$5:$C$504,$A20,Lancamentos!$G$5:$G$504,J$3) | ... N20: =SUMIFS(Lancamentos!$E$5:$E$504,Lancamentos!$B$5:$B$504,"Receita",Lancamentos!$C$5:$C$504,$A20,Lancamentos!$G$5:$G$504,N$3) | O20: =SUM(C20:N20) | P20: =AVERAGE(C20:N20)
A21: Freelance / Renda Extra | C21: =SUMIFS(Lancamentos!$E$5:$E$504,Lancamentos!$B$5:$B$504,"Receita",Lancamentos!$C$5:$C$504,$A21,Lancamentos!$G$5:$G$504,C$3) | D21: =SUMIFS(Lancamentos!$E$5:$E$504,Lancamentos!$B$5:$B$504,"Receita",Lancamentos!$C$5:$C$504,$A21,Lancamentos!$G$5:$G$504,D$3) | E21: =SUMIFS(Lancamentos!$E$5:$E$504,Lancamentos!$B$5:$B$504,"Receita",Lancamentos!$C$5:$C$504,$A21,Lancamentos!$G$5:$G$504,E$3) | F21: =SUMIFS(Lancamentos!$E$5:$E$504,Lancamentos!$B$5:$B$504,"Receita",Lancamentos!$C$5:$C$504,$A21,Lancamentos!$G$5:$G$504,F$3) | G21: =SUMIFS(Lancamentos!$E$5:$E$504,Lancamentos!$B$5:$B$504,"Receita",Lancamentos!$C$5:$C$504,$A21,Lancamentos!$G$5:$G$504,G$3) | H21: =SUMIFS(Lancamentos!$E$5:$E$504,Lancamentos!$B$5:$B$504,"Receita",Lancamentos!$C$5:$C$504,$A21,Lancamentos!$G$5:$G$504,H$3) | I21: =SUMIFS(Lancamentos!$E$5:$E$504,Lancamentos!$B$5:$B$504,"Receita",Lancamentos!$C$5:$C$504,$A21,Lancamentos!$G$5:$G$504,I$3) | J21: =SUMIFS(Lancamentos!$E$5:$E$504,Lancamentos!$B$5:$B$504,"Receita",Lancamentos!$C$5:$C$504,$A21,Lancamentos!$G$5:$G$504,J$3) | ... N21: =SUMIFS(Lancamentos!$E$5:$E$504,Lancamentos!$B$5:$B$504,"Receita",Lancamentos!$C$5:$C$504,$A21,Lancamentos!$G$5:$G$504,N$3) | O21: =SUM(C21:N21) | P21: =AVERAGE(C21:N21)
A22: Dividendos e Proventos | C22: =SUMIFS(Lancamentos!$E$5:$E$504,Lancamentos!$B$5:$B$504,"Receita",Lancamentos!$C$5:$C$504,$A22,Lancamentos!$G$5:$G$504,C$3) | D22: =SUMIFS(Lancamentos!$E$5:$E$504,Lancamentos!$B$5:$B$504,"Receita",Lancamentos!$C$5:$C$504,$A22,Lancamentos!$G$5:$G$504,D$3) | E22: =SUMIFS(Lancamentos!$E$5:$E$504,Lancamentos!$B$5:$B$504,"Receita",Lancamentos!$C$5:$C$504,$A22,Lancamentos!$G$5:$G$504,E$3) | F22: =SUMIFS(Lancamentos!$E$5:$E$504,Lancamentos!$B$5:$B$504,"Receita",Lancamentos!$C$5:$C$504,$A22,Lancamentos!$G$5:$G$504,F$3) | G22: =SUMIFS(Lancamentos!$E$5:$E$504,Lancamentos!$B$5:$B$504,"Receita",Lancamentos!$C$5:$C$504,$A22,Lancamentos!$G$5:$G$504,G$3) | H22: =SUMIFS(Lancamentos!$E$5:$E$504,Lancamentos!$B$5:$B$504,"Receita",Lancamentos!$C$5:$C$504,$A22,Lancamentos!$G$5:$G$504,H$3) | I22: =SUMIFS(Lancamentos!$E$5:$E$504,Lancamentos!$B$5:$B$504,"Receita",Lancamentos!$C$5:$C$504,$A22,Lancamentos!$G$5:$G$504,I$3) | J22: =SUMIFS(Lancamentos!$E$5:$E$504,Lancamentos!$B$5:$B$504,"Receita",Lancamentos!$C$5:$C$504,$A22,Lancamentos!$G$5:$G$504,J$3) | ... N22: =SUMIFS(Lancamentos!$E$5:$E$504,Lancamentos!$B$5:$B$504,"Receita",Lancamentos!$C$5:$C$504,$A22,Lancamentos!$G$5:$G$504,N$3) | O22: =SUM(C22:N22) | P22: =AVERAGE(C22:N22)
A23: Aluguéis | C23: =SUMIFS(Lancamentos!$E$5:$E$504,Lancamentos!$B$5:$B$504,"Receita",Lancamentos!$C$5:$C$504,$A23,Lancamentos!$G$5:$G$504,C$3) | D23: =SUMIFS(Lancamentos!$E$5:$E$504,Lancamentos!$B$5:$B$504,"Receita",Lancamentos!$C$5:$C$504,$A23,Lancamentos!$G$5:$G$504,D$3) | E23: =SUMIFS(Lancamentos!$E$5:$E$504,Lancamentos!$B$5:$B$504,"Receita",Lancamentos!$C$5:$C$504,$A23,Lancamentos!$G$5:$G$504,E$3) | F23: =SUMIFS(Lancamentos!$E$5:$E$504,Lancamentos!$B$5:$B$504,"Receita",Lancamentos!$C$5:$C$504,$A23,Lancamentos!$G$5:$G$504,F$3) | G23: =SUMIFS(Lancamentos!$E$5:$E$504,Lancamentos!$B$5:$B$504,"Receita",Lancamentos!$C$5:$C$504,$A23,Lancamentos!$G$5:$G$504,G$3) | H23: =SUMIFS(Lancamentos!$E$5:$E$504,Lancamentos!$B$5:$B$504,"Receita",Lancamentos!$C$5:$C$504,$A23,Lancamentos!$G$5:$G$504,H$3) | I23: =SUMIFS(Lancamentos!$E$5:$E$504,Lancamentos!$B$5:$B$504,"Receita",Lancamentos!$C$5:$C$504,$A23,Lancamentos!$G$5:$G$504,I$3) | J23: =SUMIFS(Lancamentos!$E$5:$E$504,Lancamentos!$B$5:$B$504,"Receita",Lancamentos!$C$5:$C$504,$A23,Lancamentos!$G$5:$G$504,J$3) | ... N23: =SUMIFS(Lancamentos!$E$5:$E$504,Lancamentos!$B$5:$B$504,"Receita",Lancamentos!$C$5:$C$504,$A23,Lancamentos!$G$5:$G$504,N$3) | O23: =SUM(C23:N23) | P23: =AVERAGE(C23:N23)
A24: Reembolsos | C24: =SUMIFS(Lancamentos!$E$5:$E$504,Lancamentos!$B$5:$B$504,"Receita",Lancamentos!$C$5:$C$504,$A24,Lancamentos!$G$5:$G$504,C$3) | D24: =SUMIFS(Lancamentos!$E$5:$E$504,Lancamentos!$B$5:$B$504,"Receita",Lancamentos!$C$5:$C$504,$A24,Lancamentos!$G$5:$G$504,D$3) | E24: =SUMIFS(Lancamentos!$E$5:$E$504,Lancamentos!$B$5:$B$504,"Receita",Lancamentos!$C$5:$C$504,$A24,Lancamentos!$G$5:$G$504,E$3) | F24: =SUMIFS(Lancamentos!$E$5:$E$504,Lancamentos!$B$5:$B$504,"Receita",Lancamentos!$C$5:$C$504,$A24,Lancamentos!$G$5:$G$504,F$3) | G24: =SUMIFS(Lancamentos!$E$5:$E$504,Lancamentos!$B$5:$B$504,"Receita",Lancamentos!$C$5:$C$504,$A24,Lancamentos!$G$5:$G$504,G$3) | H24: =SUMIFS(Lancamentos!$E$5:$E$504,Lancamentos!$B$5:$B$504,"Receita",Lancamentos!$C$5:$C$504,$A24,Lancamentos!$G$5:$G$504,H$3) | I24: =SUMIFS(Lancamentos!$E$5:$E$504,Lancamentos!$B$5:$B$504,"Receita",Lancamentos!$C$5:$C$504,$A24,Lancamentos!$G$5:$G$504,I$3) | J24: =SUMIFS(Lancamentos!$E$5:$E$504,Lancamentos!$B$5:$B$504,"Receita",Lancamentos!$C$5:$C$504,$A24,Lancamentos!$G$5:$G$504,J$3) | ... N24: =SUMIFS(Lancamentos!$E$5:$E$504,Lancamentos!$B$5:$B$504,"Receita",Lancamentos!$C$5:$C$504,$A24,Lancamentos!$G$5:$G$504,N$3) | O24: =SUM(C24:N24) | P24: =AVERAGE(C24:N24)
A25: Outras Receitas | C25: =SUMIFS(Lancamentos!$E$5:$E$504,Lancamentos!$B$5:$B$504,"Receita",Lancamentos!$C$5:$C$504,$A25,Lancamentos!$G$5:$G$504,C$3) | D25: =SUMIFS(Lancamentos!$E$5:$E$504,Lancamentos!$B$5:$B$504,"Receita",Lancamentos!$C$5:$C$504,$A25,Lancamentos!$G$5:$G$504,D$3) | E25: =SUMIFS(Lancamentos!$E$5:$E$504,Lancamentos!$B$5:$B$504,"Receita",Lancamentos!$C$5:$C$504,$A25,Lancamentos!$G$5:$G$504,E$3) | F25: =SUMIFS(Lancamentos!$E$5:$E$504,Lancamentos!$B$5:$B$504,"Receita",Lancamentos!$C$5:$C$504,$A25,Lancamentos!$G$5:$G$504,F$3) | G25: =SUMIFS(Lancamentos!$E$5:$E$504,Lancamentos!$B$5:$B$504,"Receita",Lancamentos!$C$5:$C$504,$A25,Lancamentos!$G$5:$G$504,G$3) | H25: =SUMIFS(Lancamentos!$E$5:$E$504,Lancamentos!$B$5:$B$504,"Receita",Lancamentos!$C$5:$C$504,$A25,Lancamentos!$G$5:$G$504,H$3) | I25: =SUMIFS(Lancamentos!$E$5:$E$504,Lancamentos!$B$5:$B$504,"Receita",Lancamentos!$C$5:$C$504,$A25,Lancamentos!$G$5:$G$504,I$3) | J25: =SUMIFS(Lancamentos!$E$5:$E$504,Lancamentos!$B$5:$B$504,"Receita",Lancamentos!$C$5:$C$504,$A25,Lancamentos!$G$5:$G$504,J$3) | ... N25: =SUMIFS(Lancamentos!$E$5:$E$504,Lancamentos!$B$5:$B$504,"Receita",Lancamentos!$C$5:$C$504,$A25,Lancamentos!$G$5:$G$504,N$3) | O25: =SUM(C25:N25) | P25: =AVERAGE(C25:N25)
A26: TOTAL DE RECEITAS | C26: =SUM(C20:C25) | D26: =SUM(D20:D25) | E26: =SUM(E20:E25) | F26: =SUM(F20:F25) | G26: =SUM(G20:G25) | H26: =SUM(H20:H25) | I26: =SUM(I20:I25) | J26: =SUM(J20:J25) | ... N26: =SUM(N20:N25) | O26: =SUM(C26:N26) | P26: =AVERAGE(C26:N26)
A28: APORTES EM INVESTIMENTOS | C28: =SUMIFS(Lancamentos!$E$5:$E$504,Lancamentos!$B$5:$B$504,"Investimento",Lancamentos!$G$5:$G$504,C$3) | D28: =SUMIFS(Lancamentos!$E$5:$E$504,Lancamentos!$B$5:$B$504,"Investimento",Lancamentos!$G$5:$G$504,D$3) | E28: =SUMIFS(Lancamentos!$E$5:$E$504,Lancamentos!$B$5:$B$504,"Investimento",Lancamentos!$G$5:$G$504,E$3) | F28: =SUMIFS(Lancamentos!$E$5:$E$504,Lancamentos!$B$5:$B$504,"Investimento",Lancamentos!$G$5:$G$504,F$3) | G28: =SUMIFS(Lancamentos!$E$5:$E$504,Lancamentos!$B$5:$B$504,"Investimento",Lancamentos!$G$5:$G$504,G$3) | H28: =SUMIFS(Lancamentos!$E$5:$E$504,Lancamentos!$B$5:$B$504,"Investimento",Lancamentos!$G$5:$G$504,H$3) | I28: =SUMIFS(Lancamentos!$E$5:$E$504,Lancamentos!$B$5:$B$504,"Investimento",Lancamentos!$G$5:$G$504,I$3) | J28: =SUMIFS(Lancamentos!$E$5:$E$504,Lancamentos!$B$5:$B$504,"Investimento",Lancamentos!$G$5:$G$504,J$3) | ... N28: =SUMIFS(Lancamentos!$E$5:$E$504,Lancamentos!$B$5:$B$504,"Investimento",Lancamentos!$G$5:$G$504,N$3) | O28: =SUM(C28:N28)
A29: SALDO DO MÊS (sobra em conta) | C29: =C26-C17-C28 | D29: =D26-D17-D28 | E29: =E26-E17-E28 | F29: =F26-F17-F28 | G29: =G26-G17-G28 | H29: =H26-H17-H28 | I29: =I26-I17-I28 | J29: =J26-J17-J28 | ... N29: =N26-N17-N28 | O29: =SUM(C29:N29)
A30: TAXA DE POUPANÇA (%) | C30: =IFERROR((C26-C17)/C26,"") | D30: =IFERROR((D26-D17)/D26,"") | E30: =IFERROR((E26-E17)/E26,"") | F30: =IFERROR((F26-F17)/F26,"") | G30: =IFERROR((G26-G17)/G26,"") | H30: =IFERROR((H26-H17)/H26,"") | I30: =IFERROR((I26-I17)/I26,"") | J30: =IFERROR((J26-J17)/J26,"") | ... O30: =IFERROR((O26-O17)/O26,"")

Sheet Carteira
A1: 📈 CARTEIRA DE INVESTIMENTOS — AÇÕES, FIIs, ETFs | O1: 🏠 Início
A2: Edite apenas as colunas amarelas: Quantidade, Preço Médio, Preço Atual, Alvo % e Dividendos 12m. O restante (resultado, rentabilidade, alocação e rebalanceamento) é automático.
A4: Ticker | B4: Classe | C4: Qtd. | D4: Preço Médio | E4: Preço Atual | F4: Total Investido | G4: Valor Atual | H4: Resultado (R$) | I4: Result. (%) | J4: % Carteira | K4: Alvo % | L4: Dividendos 12m | M4: Yield s/ Custo | N4: Retorno Total % | O4: Rebalancear (R$)
A5: PETR4 | B5: Ação | C5: 200 | D5: 32.5 | E5: 38.2 | F5: =IF($A5="","",C5*D5) | G5: =IF($A5="","",C5*E5) | H5: =IF($A5="","",G5-F5) | I5: =IF($A5="","",IFERROR(H5/F5,0)) | J5: =IF($A5="","",IFERROR(G5/$G$25,0)) | K5: 0.1 | L5: 980 | M5: =IF($A5="","",IFERROR(L5/F5,0)) | N5: =IF($A5="","",IFERROR((H5+L5)/F5,0)) | O5: =IF($A5="","",K5*$G$25-G5)
A6: VALE3 | B6: Ação | C6: 300 | D6: 61.8 | E6: 55.4 | F6: =IF($A6="","",C6*D6) | G6: =IF($A6="","",C6*E6) | H6: =IF($A6="","",G6-F6) | I6: =IF($A6="","",IFERROR(H6/F6,0)) | J6: =IF($A6="","",IFERROR(G6/$G$25,0)) | K6: 0.1 | L6: 1240 | M6: =IF($A6="","",IFERROR(L6/F6,0)) | N6: =IF($A6="","",IFERROR((H6+L6)/F6,0)) | O6: =IF($A6="","",K6*$G$25-G6)
A7: ITUB4 | B7: Ação | C7: 400 | D7: 27.3 | E7: 34.1 | F7: =IF($A7="","",C7*D7) | G7: =IF($A7="","",C7*E7) | H7: =IF($A7="","",G7-F7) | I7: =IF($A7="","",IFERROR(H7/F7,0)) | J7: =IF($A7="","",IFERROR(G7/$G$25,0)) | K7: 0.1 | L7: 690 | M7: =IF($A7="","",IFERROR(L7/F7,0)) | N7: =IF($A7="","",IFERROR((H7+L7)/F7,0)) | O7: =IF($A7="","",K7*$G$25-G7)
A8: BBAS3 | B8: Ação | C8: 250 | D8: 26.5 | E8: 28.9 | F8: =IF($A8="","",C8*D8) | G8: =IF($A8="","",C8*E8) | H8: =IF($A8="","",G8-F8) | I8: =IF($A8="","",IFERROR(H8/F8,0)) | J8: =IF($A8="","",IFERROR(G8/$G$25,0)) | K8: 0.08 | L8: 720 | M8: =IF($A8="","",IFERROR(L8/F8,0)) | N8: =IF($A8="","",IFERROR((H8+L8)/F8,0)) | O8: =IF($A8="","",K8*$G$25-G8)
A9: WEGE3 | B9: Ação | C9: 150 | D9: 36.4 | E9: 41.75 | F9: =IF($A9="","",C9*D9) | G9: =IF($A9="","",C9*E9) | H9: =IF($A9="","",G9-F9) | I9: =IF($A9="","",IFERROR(H9/F9,0)) | J9: =IF($A9="","",IFERROR(G9/$G$25,0)) | K9: 0.07 | L9: 95 | M9: =IF($A9="","",IFERROR(L9/F9,0)) | N9: =IF($A9="","",IFERROR((H9+L9)/F9,0)) | O9: =IF($A9="","",K9*$G$25-G9)
A10: TAEE11 | B10: Ação | C10: 200 | D10: 34.2 | E10: 36.1 | F10: =IF($A10="","",C10*D10) | G10: =IF($A10="","",C10*E10) | H10: =IF($A10="","",G10-F10) | I10: =IF($A10="","",IFERROR(H10/F10,0)) | J10: =IF($A10="","",IFERROR(G10/$G$25,0)) | K10: 0.05 | L10: 610 | M10: =IF($A10="","",IFERROR(L10/F10,0)) | N10: =IF($A10="","",IFERROR((H10+L10)/F10,0)) | O10: =IF($A10="","",K10*$G$25-G10)
A11: B3SA3 | B11: Ação | C11: 500 | D11: 10.8 | E11: 12.35 | F11: =IF($A11="","",C11*D11) | G11: =IF($A11="","",C11*E11) | H11: =IF($A11="","",G11-F11) | I11: =IF($A11="","",IFERROR(H11/F11,0)) | J11: =IF($A11="","",IFERROR(G11/$G$25,0)) | K11: 0.05 | L11: 310 | M11: =IF($A11="","",IFERROR(L11/F11,0)) | N11: =IF($A11="","",IFERROR((H11+L11)/F11,0)) | O11: =IF($A11="","",K11*$G$25-G11)
A12: KNRI11 | B12: FII | C12: 80 | D12: 152 | E12: 161.5 | F12: =IF($A12="","",C12*D12) | G12: =IF($A12="","",C12*E12) | H12: =IF($A12="","",G12-F12) | I12: =IF($A12="","",IFERROR(H12/F12,0)) | J12: =IF($A12="","",IFERROR(G12/$G$25,0)) | K12: 0.1 | L12: 1050 | M12: =IF($A12="","",IFERROR(L12/F12,0)) | N12: =IF($A12="","",IFERROR((H12+L12)/F12,0)) | O12: =IF($A12="","",K12*$G$25-G12)
A13: HGLG11 | B13: FII | C13: 60 | D13: 158.3 | E13: 165.2 | F13: =IF($A13="","",C13*D13) | G13: =IF($A13="","",C13*E13) | H13: =IF($A13="","",G13-F13) | I13: =IF($A13="","",IFERROR(H13/F13,0)) | J13: =IF($A13="","",IFERROR(G13/$G$25,0)) | K13: 0.1 | L13: 880 | M13: =IF($A13="","",IFERROR(L13/F13,0)) | N13: =IF($A13="","",IFERROR((H13+L13)/F13,0)) | O13: =IF($A13="","",K13*$G$25-G13)
A14: IVVB11 | B14: ETF | C14: 50 | D14: 280 | E14: 341.6 | F14: =IF($A14="","",C14*D14) | G14: =IF($A14="","",C14*E14) | H14: =IF($A14="","",G14-F14) | I14: =IF($A14="","",IFERROR(H14/F14,0)) | J14: =IF($A14="","",IFERROR(G14/$G$25,0)) | K14: 0.25 | L14: 0 | M14: =IF($A14="","",IFERROR(L14/F14,0)) | N14: =IF($A14="","",IFERROR((H14+L14)/F14,0)) | O14: =IF($A14="","",K14*$G$25-G14)
F15: =IF($A15="","",C15*D15) | G15: =IF($A15="","",C15*E15) | H15: =IF($A15="","",G15-F15) | I15: =IF($A15="","",IFERROR(H15/F15,0)) | J15: =IF($A15="","",IFERROR(G15/$G$25,0)) | M15: =IF($A15="","",IFERROR(L15/F15,0)) | N15: =IF($A15="","",IFERROR((H15+L15)/F15,0)) | O15: =IF($A15="","",K15*$G$25-G15)
F16: =IF($A16="","",C16*D16) | G16: =IF($A16="","",C16*E16) | H16: =IF($A16="","",G16-F16) | I16: =IF($A16="","",IFERROR(H16/F16,0)) | J16: =IF($A16="","",IFERROR(G16/$G$25,0)) | M16: =IF($A16="","",IFERROR(L16/F16,0)) | N16: =IF($A16="","",IFERROR((H16+L16)/F16,0)) | O16: =IF($A16="","",K16*$G$25-G16)
F17: =IF($A17="","",C17*D17) | G17: =IF($A17="","",C17*E17) | H17: =IF($A17="","",G17-F17) | I17: =IF($A17="","",IFERROR(H17/F17,0)) | J17: =IF($A17="","",IFERROR(G17/$G$25,0)) | M17: =IF($A17="","",IFERROR(L17/F17,0)) | N17: =IF($A17="","",IFERROR((H17+L17)/F17,0)) | O17: =IF($A17="","",K17*$G$25-G17)
F18: =IF($A18="","",C18*D18) | G18: =IF($A18="","",C18*E18) | H18: =IF($A18="","",G18-F18) | I18: =IF($A18="","",IFERROR(H18/F18,0)) | J18: =IF($A18="","",IFERROR(G18/$G$25,0)) | M18: =IF($A18="","",IFERROR(L18/F18,0)) | N18: =IF($A18="","",IFERROR((H18+L18)/F18,0)) | O18: =IF($A18="","",K18*$G$25-G18)
F19: =IF($A19="","",C19*D19) | G19: =IF($A19="","",C19*E19) | H19: =IF($A19="","",G19-F19) | I19: =IF($A19="","",IFERROR(H19/F19,0)) | J19: =IF($A19="","",IFERROR(G19/$G$25,0)) | M19: =IF($A19="","",IFERROR(L19/F19,0)) | N19: =IF($A19="","",IFERROR((H19+L19)/F19,0)) | O19: =IF($A19="","",K19*$G$25-G19)
F20: =IF($A20="","",C20*D20) | G20: =IF($A20="","",C20*E20) | H20: =IF($A20="","",G20-F20) | I20: =IF($A20="","",IFERROR(H20/F20,0)) | J20: =IF($A20="","",IFERROR(G20/$G$25,0)) | M20: =IF($A20="","",IFERROR(L20/F20,0)) | N20: =IF($A20="","",IFERROR((H20+L20)/F20,0)) | O20: =IF($A20="","",K20*$G$25-G20)
F21: =IF($A21="","",C21*D21) | G21: =IF($A21="","",C21*E21) | H21: =IF($A21="","",G21-F21) | I21: =IF($A21="","",IFERROR(H21/F21,0)) | J21: =IF($A21="","",IFERROR(G21/$G$25,0)) | M21: =IF($A21="","",IFERROR(L21/F21,0)) | N21: =IF($A21="","",IFERROR((H21+L21)/F21,0)) | O21: =IF($A21="","",K21*$G$25-G21)
F22: =IF($A22="","",C22*D22) | G22: =IF($A22="","",C22*E22) | H22: =IF($A22="","",G22-F22) | I22: =IF($A22="","",IFERROR(H22/F22,0)) | J22: =IF($A22="","",IFERROR(G22/$G$25,0)) | M22: =IF($A22="","",IFERROR(L22/F22,0)) | N22: =IF($A22="","",IFERROR((H22+L22)/F22,0)) | O22: =IF($A22="","",K22*$G$25-G22)
F23: =IF($A23="","",C23*D23) | G23: =IF($A23="","",C23*E23) | H23: =IF($A23="","",G23-F23) | I23: =IF($A23="","",IFERROR(H23/F23,0)) | J23: =IF($A23="","",IFERROR(G23/$G$25,0)) | M23: =IF($A23="","",IFERROR(L23/F23,0)) | N23: =IF($A23="","",IFERROR((H23+L23)/F23,0)) | O23: =IF($A23="","",K23*$G$25-G23)
F24: =IF($A24="","",C24*D24) | G24: =IF($A24="","",C24*E24) | H24: =IF($A24="","",G24-F24) | I24: =IF($A24="","",IFERROR(H24/F24,0)) | J24: =IF($A24="","",IFERROR(G24/$G$25,0)) | M24: =IF($A24="","",IFERROR(L24/F24,0)) | N24: =IF($A24="","",IFERROR((H24+L24)/F24,0)) | O24: =IF($A24="","",K24*$G$25-G24)
A25: TOTAL DA CARTEIRA | F25: =SUM(F5:F24) | G25: =SUM(G5:G24) | H25: =G25-F25 | I25: =IFERROR(H25/F25,"") | J25: =IFERROR(G25/G25,"") | K25: =SUM(K5:K24) | L25: =SUM(L5:L24) | M25: =IFERROR(L25/F25,"") | N25: =IFERROR((H25+L25)/F25,"")
A27: Soma dos Alvos (deve dar 100%) | C27: =SUM(K5:K24) | D27: =IF(ROUND(C27,4)=1,"✔ OK","⚠ ajuste os alvos")
A29: RESUMO POR CLASSE DE ATIVO
A30: Classe | B30: Valor Atual | C30: % Carteira | D30: Alvo % | E30: Resultado R$
A31: Ação | B31: =SUMIF($B$5:$B$24,$A31,$G$5:$G$24) | C31: =IFERROR(B31/$G$25,0) | D31: =SUMIF($B$5:$B$24,$A31,$K$5:$K$24) | E31: =SUMIF($B$5:$B$24,$A31,$H$5:$H$24)
A32: FII | B32: =SUMIF($B$5:$B$24,$A32,$G$5:$G$24) | C32: =IFERROR(B32/$G$25,0) | D32: =SUMIF($B$5:$B$24,$A32,$K$5:$K$24) | E32: =SUMIF($B$5:$B$24,$A32,$H$5:$H$24)
A33: ETF | B33: =SUMIF($B$5:$B$24,$A33,$G$5:$G$24) | C33: =IFERROR(B33/$G$25,0) | D33: =SUMIF($B$5:$B$24,$A33,$K$5:$K$24) | E33: =SUMIF($B$5:$B$24,$A33,$H$5:$H$24)
A34: BDR | B34: =SUMIF($B$5:$B$24,$A34,$G$5:$G$24) | C34: =IFERROR(B34/$G$25,0) | D34: =SUMIF($B$5:$B$24,$A34,$K$5:$K$24) | E34: =SUMIF($B$5:$B$24,$A34,$H$5:$H$24)
A35: Renda Fixa | B35: =SUMIF($B$5:$B$24,$A35,$G$5:$G$24) | C35: =IFERROR(B35/$G$25,0) | D35: =SUMIF($B$5:$B$24,$A35,$K$5:$K$24) | E35: =SUMIF($B$5:$B$24,$A35,$H$5:$H$24)
A36: Cripto | B36: =SUMIF($B$5:$B$24,$A36,$G$5:$G$24) | C36: =IFERROR(B36/$G$25,0) | D36: =SUMIF($B$5:$B$24,$A36,$K$5:$K$24) | E36: =SUMIF($B$5:$B$24,$A36,$H$5:$H$24)
A38: INDICADORES DA CARTEIRA
A39: Total Investido | C39: =G25-H25
A40: Valor Atual | C40: =G25
A41: Resultado (R$) | C41: =H25
A42: Resultado (%) | C42: =IFERROR(H25/F25,0)
A43: Dividendos 12m | C43: =L25
A44: Yield da Carteira | C44: =IFERROR(L25/F25,0)
...

Sheet Patrimonio
A1: 🏦 PATRIMÔNIO LÍQUIDO & RESERVA DE EMERGÊNCIA | H1: 🏠 Início
A2: Tire uma 'foto' do seu patrimônio a cada mês (células amarelas). Patrimônio Líquido = tudo que você tem menos o que deve. Investimentos pode ser puxado da aba Carteira (total R$).
A3: 💡 Total atual da Carteira (copie na coluna Investimentos) → | D3: =Carteira!$G$25
A4: Mês | B4: Conta / Liquidez | C4: Reserva Emergência | D4: Investimentos | E4: Outros Ativos | F4: Dívidas | G4: Patrimônio Líquido | H4: Variação
A5: Jan/26 | B5: 4200 | C5: 18000 | D5: 92000 | E5: 5000 | F5: 12000 | G5: =IF(COUNT(B5:F5)=0,"",B5+C5+D5+E5-F5) | H5: =""
A6: Fev/26 | B6: 4500 | C6: 19000 | D6: 95500 | E6: 5000 | F6: 11200 | G6: =IF(COUNT(B6:F6)=0,"",B6+C6+D6+E6-F6) | H6: =IF(OR(G6="",G5=""),"",G6-G5)
A7: Mar/26 | B7: 4800 | C7: 20000 | D7: 98800 | E7: 5000 | F7: 10400 | G7: =IF(COUNT(B7:F7)=0,"",B7+C7+D7+E7-F7) | H7: =IF(OR(G7="",G6=""),"",G7-G6)
A8: Abr/26 | B8: 5100 | C8: 21000 | D8: 101200 | E8: 5000 | F8: 9600 | G8: =IF(COUNT(B8:F8)=0,"",B8+C8+D8+E8-F8) | H8: =IF(OR(G8="",G7=""),"",G8-G7)
A9: Mai/26 | B9: 5400 | C9: 22000 | D9: 103000 | E9: 5000 | F9: 8800 | G9: =IF(COUNT(B9:F9)=0,"",B9+C9+D9+E9-F9) | H9: =IF(OR(G9="",G8=""),"",G9-G8)
A10: Jun/26 | B10: 5700 | C10: 23000 | D10: 104695 | E10: 5000 | F10: 8000 | G10: =IF(COUNT(B10:F10)=0,"",B10+C10+D10+E10-F10) | H10: =IF(OR(G10="",G9=""),"",G10-G9)
G11: =IF(COUNT(B11:F11)=0,"",B11+C11+D11+E11-F11) | H11: =IF(OR(G11="",G10=""),"",G11-G10)
G12: =IF(COUNT(B12:F12)=0,"",B12+C12+D12+E12-F12) | H12: =IF(OR(G12="",G11=""),"",G12-G11)
G13: =IF(COUNT(B13:F13)=0,"",B13+C13+D13+E13-F13) | H13: =IF(OR(G13="",G12=""),"",G13-G12)
G14: =IF(COUNT(B14:F14)=0,"",B14+C14+D14+E14-F14) | H14: =IF(OR(G14="",G13=""),"",G14-G13)
G15: =IF(COUNT(B15:F15)=0,"",B15+C15+D15+E15-F15) | H15: =IF(OR(G15="",G14=""),"",G15-G14)
G16: =IF(COUNT(B16:F16)=0,"",B16+C16+D16+E16-F16) | H16: =IF(OR(G16="",G15=""),"",G16-G15)
A18: RESERVA DE EMERGÊNCIA
A19: Custo de vida mensal (R$) | B19: 6000
A20: Meses de segurança desejados | B20: 6
A21: Meta da reserva | B21: =B19*B20
A22: Reserva atual (último mês) | B22: =IFERROR(LOOKUP(2,1/(C5:C16<>""),C5:C16),0)
A23: % da meta atingida | B23: =IFERROR(B22/B21,0)
A24: Falta guardar | B24: =MAX(0,B21-B22)

Sheet Simulador
A1: 🧮 SIMULADOR DE INVESTIMENTOS — JUROS COMPOSTOS | I1: 🏠 Início
A3: PARÂMETROS (edite as células amarelas) | D3: RESULTADO NO PRAZO (cenário Moderado)
A4: Aporte inicial (R$) | B4: 10000 | D4: Patrimônio final (nominal) | E4: =IFERROR(INDEX($D$13:$D$43,MATCH($B$6,$A$13:$A$43,0)),"-")
A5: Aporte mensal (R$) | B5: 1500 | D5: Total aportado | E5: =IFERROR(INDEX($B$13:$B$43,MATCH($B$6,$A$13:$A$43,0)),"-")
A6: Prazo para análise (anos, 1 a 30) | B6: 25 | D6: Juros acumulados | E6: =IFERROR(E4-E5,"-")
A7: Inflação anual estimada | B7: 0.045 | D7: Patrimônio em valor de hoje (real) | E7: =IFERROR(E4/(1+$B$7)^$B$6,"-")
D8: Renda mensal estimada (4% a.a.) | E8: =IFERROR(E4*0.04/12,"-")
D9: Tempo p/ dobrar o capital (regra 72) | E9: =IFERROR(72/($C$11*100),"-")
A10: Taxas anuais dos cenários → | B10: Conservador | C10: Moderado | D10: Arrojado
B11: 0.08 | C11: 0.105 | D11: 0.13
A12: Ano | B12: Total Aportado | C12: Conservador | D12: Moderado | E12: Arrojado | F12: Juros (Moderado)
A13: 0 | B13: =$B$4+$B$5*12*$A13 | C13: =FV((1+$B$11)^(1/12)-1,$A13*12,-$B$5,-$B$4) | D13: =FV((1+$C$11)^(1/12)-1,$A13*12,-$B$5,-$B$4) | E13: =FV((1+$D$11)^(1/12)-1,$A13*12,-$B$5,-$B$4) | F13: =D13-B13
A14: 1 | B14: =$B$4+$B$5*12*$A14 | C14: =FV((1+$B$11)^(1/12)-1,$A14*12,-$B$5,-$B$4) | D14: =FV((1+$C$11)^(1/12)-1,$A14*12,-$B$5,-$B$4) | E14: =FV((1+$D$11)^(1/12)-1,$A14*12,-$B$5,-$B$4) | F14: =D14-B14
A15: 2 | B15: =$B$4+$B$5*12*$A15 | C15: =FV((1+$B$11)^(1/12)-1,$A15*12,-$B$5,-$B$4) | D15: =FV((1+$C$11)^(1/12)-1,$A15*12,-$B$5,-$B$4) | E15: =FV((1+$D$11)^(1/12)-1,$A15*12,-$B$5,-$B$4) | F15: =D15-B15
A16: 3 | B16: =$B$4+$B$5*12*$A16 | C16: =FV((1+$B$11)^(1/12)-1,$A16*12,-$B$5,-$B$4) | D16: =FV((1+$C$11)^(1/12)-1,$A16*12,-$B$5,-$B$4) | E16: =FV((1+$D$11)^(1/12)-1,$A16*12,-$B$5,-$B$4) | F16: =D16-B16
A17: 4 | B17: =$B$4+$B$5*12*$A17 | C17: =FV((1+$B$11)^(1/12)-1,$A17*12,-$B$5,-$B$4) | D17: =FV((1+$C$11)^(1/12)-1,$A17*12,-$B$5,-$B$4) | E17: =FV((1+$D$11)^(1/12)-1,$A17*12,-$B$5,-$B$4) | F17: =D17-B17
A18: 5 | B18: =$B$4+$B$5*12*$A18 | C18: =FV((1+$B$11)^(1/12)-1,$A18*12,-$B$5,-$B$4) | D18: =FV((1+$C$11)^(1/12)-1,$A18*12,-$B$5,-$B$4) | E18: =FV((1+$D$11)^(1/12)-1,$A18*12,-$B$5,-$B$4) | F18: =D18-B18
A19: 6 | B19: =$B$4+$B$5*12*$A19 | C19: =FV((1+$B$11)^(1/12)-1,$A19*12,-$B$5,-$B$4) | D19: =FV((1+$C$11)^(1/12)-1,$A19*12,-$B$5,-$B$4) | E19: =FV((1+$D$11)^(1/12)-1,$A19*12,-$B$5,-$B$4) | F19: =D19-B19
A20: 7 | B20: =$B$4+$B$5*12*$A20 | C20: =FV((1+$B$11)^(1/12)-1,$A20*12,-$B$5,-$B$4) | D20: =FV((1+$C$11)^(1/12)-1,$A20*12,-$B$5,-$B$4) | E20: =FV((1+$D$11)^(1/12)-1,$A20*12,-$B$5,-$B$4) | F20: =D20-B20
A21: 8 | B21: =$B$4+$B$5*12*$A21 | C21: =FV((1+$B$11)^(1/12)-1,$A21*12,-$B$5,-$B$4) | D21: =FV((1+$C$11)^(1/12)-1,$A21*12,-$B$5,-$B$4) | E21: =FV((1+$D$11)^(1/12)-1,$A21*12,-$B$5,-$B$4) | F21: =D21-B21
A22: 9 | B22: =$B$4+$B$5*12*$A22 | C22: =FV((1+$B$11)^(1/12)-1,$A22*12,-$B$5,-$B$4) | D22: =FV((1+$C$11)^(1/12)-1,$A22*12,-$B$5,-$B$4) | E22: =FV((1+$D$11)^(1/12)-1,$A22*12,-$B$5,-$B$4) | F22: =D22-B22
A23: 10 | B23: =$B$4+$B$5*12*$A23 | C23: =FV((1+$B$11)^(1/12)-1,$A23*12,-$B$5,-$B$4) | D23: =FV((1+$C$11)^(1/12)-1,$A23*12,-$B$5,-$B$4) | E23: =FV((1+$D$11)^(1/12)-1,$A23*12,-$B$5,-$B$4) | F23: =D23-B23
A24: 11 | B24: =$B$4+$B$5*12*$A24 | C24: =FV((1+$B$11)^(1/12)-1,$A24*12,-$B$5,-$B$4) | D24: =FV((1+$C$11)^(1/12)-1,$A24*12,-$B$5,-$B$4) | E24: =FV((1+$D$11)^(1/12)-1,$A24*12,-$B$5,-$B$4) | F24: =D24-B24
... A43: 30 | B43: =$B$4+$B$5*12*$A43 | C43: =FV((1+$B$11)^(1/12)-1,$A43*12,-$B$5,-$B$4) | D43: =FV((1+$C$11)^(1/12)-1,$A43*12,-$B$5,-$B$4) | E43: =FV((1+$D$11)^(1/12)-1,$A43*12,-$B$5,-$B$4) | F43: =D43-B43

Sheet Independencia
A1: 🔥 INDEPENDÊNCIA FINANCEIRA (FIRE) | I1: 🏠 Início
A3: SEUS DADOS (edite as células amarelas)
A4: Custo de vida mensal (R$) | B4: 6000
A5: Taxa de retirada segura anual | B5: 0.04
A6: Patrimônio investido hoje (R$) | B6: 85000
A7: Aporte mensal (R$) | B7: 1500
A8: Retorno real anual esperado | B8: 0.07
A9: Idade atual | B9: 30
A10: Idade-alvo de aposentadoria | B10: 60
A12: RESULTADOS | D12: MARCOS DA JORNADA
A13: Número FIRE (patrimônio-alvo) | B13: =B4*12/B5 | D13: 25% do caminho | E13: =$B$13*0.25 | F13: =IF($B$6>=E13,"✔ Atingido","Em progresso")
A14: Renda passiva mensal hoje | B14: =B6*B5/12 | D14: 50% do caminho | E14: =$B$13*0.5 | F14: =IF($B$6>=E14,"✔ Atingido","Em progresso")
A15: Progresso até a independência | B15: =MIN(1,B6/B13) | D15: 75% do caminho | E15: =$B$13*0.75 | F15: =IF($B$6>=E15,"✔ Atingido","Em progresso")
A16: Anos até a independência | B16: =IF(B6>=B13,0,IFERROR(NPER((1+B8)^(1/12)-1,-B7,-B6,B13)/12,"-")) | D16: INDEPENDÊNCIA TOTAL | E16: =$B$13*1.0 | F16: =IF($B$6>=E16,"✔ Atingido","Em progresso")
A17: Sua idade na independência | B17: =IFERROR(B9+B16,"-")
A18: Lean FIRE (custo -30%) | B18: =B4*0.7*12/B5
A19: Fat FIRE (custo +50%) | B19: =B4*1.5*12/B5
A20: Coast FIRE (precisa ter hoje) | B20: =IFERROR(B13/(1+B8)^MAX(0,B10-B9),B13)
A21: Você já é Coast FIRE? | B21: =IF(B6>=B20,"✔ SIM","Ainda não")
A22: Reserva de emergência (6× custo) | B22: =B4*6
A24: Ano | B24: Idade | C24: Patrimônio Projetado | D24: Renda Passiva Mensal | E24: Meta FIRE | F24: Status
A25: 0 | B25: =$B$9+A25 | C25: =FV((1+$B$8)^(1/12)-1,A25*12,-$B$7,-$B$6) | D25: =C25*$B$5/12 | E25: =$B$13 | F25: =IF(C25>=$B$13,"🏆 LIVRE","—")
A26: 1 | B26: =$B$9+A26 | C26: =FV((1+$B$8)^(1/12)-1,A26*12,-$B$7,-$B$6) | D26: =C26*$B$5/12 | E26: =$B$13 | F26: =IF(C26>=$B$13,"🏆 LIVRE","—")
A27: 2 | B27: =$B$9+A27 | C27: =FV((1+$B$8)^(1/12)-1,A27*12,-$B$7,-$B$6) | D27: =C27*$B$5/12 | E27: =$B$13 | F27: =IF(C27>=$B$13,"🏆 LIVRE","—")
A28: 3 | B28: =$B$9+A28 | C28: =FV((1+$B$8)^(1/12)-1,A28*12,-$B$7,-$B$6) | D28: =C28*$B$5/12 | E28: =$B$13 | F28: =IF(C28>=$B$13,"🏆 LIVRE","—")
A29: 4 | B29: =$B$9+A29 | C29: =FV((1+$B$8)^(1/12)-1,A29*12,-$B$7,-$B$6) | D29: =C29*$B$5/12 | E29: =$B$13 | F29: =IF(C29>=$B$13,"🏆 LIVRE","—")
A30: 5 | B30: =$B$9+A30 | C30: =FV((1+$B$8)^(1/12)-1,A30*12,-$B$7,-$B$6) | D30: =C30*$B$5/12 | E30: =$B$13 | F30: =IF(C30>=$B$13,"🏆 LIVRE","—")
A31: 6 | B31: =$B$9+A31 | C31: =FV((1+$B$8)^(1/12)-1,A31*12,-$B$7,-$B$6) | D31: =C31*$B$5/12 | E31: =$B$13 | F31: =IF(C31>=$B$13,"🏆 LIVRE","—")
A32: 7 | B32: =$B$9+A32 | C32: =FV((1+$B$8)^(1/12)-1,A32*12,-$B$7,-$B$6) | D32: =C32*$B$5/12 | E32: =$B$13 | F32: =IF(C32>=$B$13,"🏆 LIVRE","—")
A33: 8 | B33: =$B$9+A33 | C33: =FV((1+$B$8)^(1/12)-1,A33*12,-$B$7,-$B$6) | D33: =C33*$B$5/12 | E33: =$B$13 | F33: =IF(C33>=$B$13,"🏆 LIVRE","—")
A34: 9 | B34: =$B$9+A34 | C34: =FV((1+$B$8)^(1/12)-1,A34*12,-$B$7,-$B$6) | D34: =C34*$B$5/12 | E34: =$B$13 | F34: =IF(C34>=$B$13,"🏆 LIVRE","—")
A35: 10 | B35: =$B$9+A35 | C35: =FV((1+$B$8)^(1/12)-1,A35*12,-$B$7,-$B$6) | D35: =C35*$B$5/12 | E35: =$B$13 | F35: =IF(C35>=$B$13,"🏆 LIVRE","—")
A36: 11 | B36: =$B$9+A36 | C36: =FV((1+$B$8)^(1/12)-1,A36*12,-$B$7,-$B$6) | D36: =C36*$B$5/12 | E36: =$B$13 | F36: =IF(C36>=$B$13,"🏆 LIVRE","—")
... A65: 40 | B65: =$B$9+A65 | C65: =FV((1+$B$8)^(1/12)-1,A65*12,-$B$7,-$B$6) | D65: =C65*$B$5/12 | E65: =$B$13 | F65: =IF(C65>=$B$13,"🏆 LIVRE","—")

Sheet Metas
A1: 🎯 METAS FINANCEIRAS | I1: 🏠 Início
A2: Defina suas metas (células amarelas). A planilha calcula quanto falta, o % concluído e o APORTE MENSAL necessário para chegar no prazo. Atualize a data-base abaixo.
A3: Data-base (hoje): | B3: 46190
A4: Meta | B4: Valor Alvo | C4: Valor Atual | D4: Prazo (data) | E4: Falta | F4: % Concluído | G4: Meses Restantes | H4: Aporte Mensal Necessário | I4: Status
A5: Reserva de emergência | B5: 36000 | C5: 23000 | D5: 46387 | E5: =IF($A5="","",MAX(0,B5-C5)) | F5: =IF($A5="","",IFERROR(MIN(1,C5/B5),0)) | G5: =IF($A5="","",MAX(1,DATEDIF($B$3,D5,"m"))) | H5: =IF($A5="","",IFERROR(E5/G5,0)) | I5: =IF($A5="","",IF(F5>=1,"✔ Concluída",IF($B$3>D5,"⚠ Prazo vencido","Em andamento")))
A6: Viagem internacional | B6: 15000 | C6: 4000 | D6: 46402 | E6: =IF($A6="","",MAX(0,B6-C6)) | F6: =IF($A6="","",IFERROR(MIN(1,C6/B6),0)) | G6: =IF($A6="","",MAX(1,DATEDIF($B$3,D6,"m"))) | H6: =IF($A6="","",IFERROR(E6/G6,0)) | I6: =IF($A6="","",IF(F6>=1,"✔ Concluída",IF($B$3>D6,"⚠ Prazo vencido","Em andamento")))
A7: Entrada do apartamento | B7: 80000 | C7: 18000 | D7: 47299 | E7: =IF($A7="","",MAX(0,B7-C7)) | F7: =IF($A7="","",IFERROR(MIN(1,C7/B7),0)) | G7: =IF($A7="","",MAX(1,DATEDIF($B$3,D7,"m"))) | H7: =IF($A7="","",IFERROR(E7/G7,0)) | I7: =IF($A7="","",IF(F7>=1,"✔ Concluída",IF($B$3>D7,"⚠ Prazo vencido","Em andamento")))
A8: Troca de carro | B8: 45000 | C8: 9000 | D8: 46813 | E8: =IF($A8="","",MAX(0,B8-C8)) | F8: =IF($A8="","",IFERROR(MIN(1,C8/B8),0)) | G8: =IF($A8="","",MAX(1,DATEDIF($B$3,D8,"m"))) | H8: =IF($A8="","",IFERROR(E8/G8,0)) | I8: =IF($A8="","",IF(F8>=1,"✔ Concluída",IF($B$3>D8,"⚠ Prazo vencido","Em andamento")))
A9: Curso de especialização | B9: 12000 | C9: 3000 | D9: 46266 | E9: =IF($A9="","",MAX(0,B9-C9)) | F9: =IF($A9="","",IFERROR(MIN(1,C9/B9),0)) | G9: =IF($A9="","",MAX(1,DATEDIF($B$3,D9,"m"))) | H9: =IF($A9="","",IFERROR(E9/G9,0)) | I9: =IF($A9="","",IF(F9>=1,"✔ Concluída",IF($B$3>D9,"⚠ Prazo vencido","Em andamento")))
E10: =IF($A10="","",MAX(0,B10-C10)) | F10: =IF($A10="","",IFERROR(MIN(1,C10/B10),0)) | G10: =IF($A10="","",MAX(1,DATEDIF($B$3,D10,"m"))) | H10: =IF($A10="","",IFERROR(E10/G10,0)) | I10: =IF($A10="","",IF(F10>=1,"✔ Concluída",IF($B$3>D10,"⚠ Prazo vencido","Em andamento")))
E11: =IF($A11="","",MAX(0,B11-C11)) | F11: =IF($A11="","",IFERROR(MIN(1,C11/B11),0)) | G11: =IF($A11="","",MAX(1,DATEDIF($B$3,D11,"m"))) | H11: =IF($A11="","",IFERROR(E11/G11,0)) | I11: =IF($A11="","",IF(F11>=1,"✔ Concluída",IF($B$3>D11,"⚠ Prazo vencido","Em andamento")))
E12: =IF($A12="","",MAX(0,B12-C12)) | F12: =IF($A12="","",IFERROR(MIN(1,C12/B12),0)) | G12: =IF($A12="","",MAX(1,DATEDIF($B$3,D12,"m"))) | H12: =IF($A12="","",IFERROR(E12/G12,0)) | I12: =IF($A12="","",IF(F12>=1,"✔ Concluída",IF($B$3>D12,"⚠ Prazo vencido","Em andamento")))
E13: =IF($A13="","",MAX(0,B13-C13)) | F13: =IF($A13="","",IFERROR(MIN(1,C13/B13),0)) | G13: =IF($A13="","",MAX(1,DATEDIF($B$3,D13,"m"))) | H13: =IF($A13="","",IFERROR(E13/G13,0)) | I13: =IF($A13="","",IF(F13>=1,"✔ Concluída",IF($B$3>D13,"⚠ Prazo vencido","Em andamento")))
E14: =IF($A14="","",MAX(0,B14-C14)) | F14: =IF($A14="","",IFERROR(MIN(1,C14/B14),0)) | G14: =IF($A14="","",MAX(1,DATEDIF($B$3,D14,"m"))) | H14: =IF($A14="","",IFERROR(E14/G14,0)) | I14: =IF($A14="","",IF(F14>=1,"✔ Concluída",IF($B$3>D14,"⚠ Prazo vencido","Em andamento")))

Sheet Instrucoes
A1: 📖 COMO USAR ESTA PLANILHA
A2: VISÃO GERAL
B3: Esta planilha reúne 6 ferramentas integradas: controle financeiro (Lançamentos), orçamento doméstico (Orçamento), carteira de investimentos (Carteira), patrimônio líquido e reserva (Patrimônio), simulador de juros compostos (Simulador), independência financeira (Independência) e metas (Metas). O Dashboard resume tudo automaticamente e a aba Início serve de menu.
B4: REGRA DE OURO: você só edita as células AMARELAS e a aba Lançamentos. Todo o resto é fórmula e se calcula sozinho.
A5: 1) LANÇAMENTOS — o coração da planilha
B6: Registre cada movimentação: Data, Tipo (Receita/Despesa/Investimento), Categoria, Descrição, Valor e Forma de Pagamento. Os menus suspensos evitam erros. Use o tipo 'Investimento' para aportes — assim eles não contam como despesa e sua taxa de poupança fica correta. A coluna Saldo em Caixa mostra o acumulado (mantenha os lançamentos em ordem de data, sem linhas vazias no meio).
A7: 2) ORÇAMENTO — planejado × realizado
B8: Defina na coluna B quanto pretende gastar por mês em cada categoria. O realizado vem sozinho dos lançamentos. Célula vermelha = mês acima do orçado. A coluna '% Usado' mostra quanto do orçamento anual já foi consumido. Acompanhe SALDO DO MÊS e TAXA DE POUPANÇA (poupar 20%+ da renda é uma ótima referência).
A9: 3) CARTEIRA — seus investimentos
B10: Cadastre cada ativo: Quantidade, Preço Médio, Preço Atual, Alvo % (quanto você quer ter naquele ativo) e Dividendos 12m. A planilha calcula resultado em R$ e %, % da carteira, yield sobre custo, retorno total (com dividendos) e REBALANCEAR (quanto comprar = positivo, ou vender = negativo, para voltar ao seu alvo). Confira se a soma dos Alvos dá 100% (há um verificador). O Resumo por Classe e os gráficos mostram sua diversificação.
A11: 4) PATRIMÔNIO — quanto você realmente tem
B12: A cada mês registre Conta/Liquidez, Reserva, Investimentos (pode puxar o total da Carteira), Outros Ativos e Dívidas. O Patrimônio Líquido e a Variação são automáticos. No bloco da reserva de emergência, defina seu custo mensal e os meses de segurança — a meta e o % atingido aparecem na hora.
A13: 5) SIMULADOR — o poder dos juros compostos
B14: Informe aporte inicial, aporte mensal, prazo e inflação. Compare 3 cenários (taxas editáveis), veja o patrimônio em valor de hoje (descontada a inflação), a renda mensal estimada e quanto do resultado veio de juros — não do seu bolso.
A15: 6) INDEPENDÊNCIA (FIRE) — sua liberdade tem um número
B16: Número FIRE = custo de vida anual ÷ taxa de retirada segura (padrão 4%). A planilha calcula em quantos anos você chega lá, sua idade na independência, as variações Lean/Fat FIRE e o Coast FIRE (quanto bastaria ter hoje para, sem novos aportes, chegar à meta na idade-alvo). Use o RETORNO REAL (acima da inflação): 6% a 8% a.a. é uma faixa razoável.
A17: 7) METAS — transforme sonhos em plano
B18: Cadastre cada objetivo com valor alvo, valor atual e prazo. A planilha mostra quanto falta, o % concluído e o APORTE MENSAL necessário para chegar no prazo. Mantenha a data-base atualizada.
A19: DICAS PARA EXTRAIR O MÁXIMO
B20: • Reserve 10 minutos por semana para lançar gastos e atualizar preços — consistência vale mais que perfeição.
